Sender: LSF System <lsfadmin@eu-g1-026-4>
Subject: Job 162438580: <python COSA_main.py> in cluster <euler> Exited

Job <python COSA_main.py> was submitted from host <eu-login-20> by user <anunezji> in cluster <euler> at Wed Feb 10 09:03:21 2021
Job was executed on host(s) <48*eu-g1-026-4>, in queue <bigmem.24h>, as user <anunezji> in cluster <euler> at Wed Feb 10 09:03:48 2021
</cluster/home/anunezji> was used as the home directory.
</cluster/home/anunezji> was used as the working directory.
Started at Wed Feb 10 09:03:48 2021
Terminated at Wed Feb 10 09:31:14 2021
Results reported at Wed Feb 10 09:31:14 2021

Your job looked like:

------------------------------------------------------------
# LSBATCH: User input
python COSA_main.py
------------------------------------------------------------

Exited with exit code 1.

Resource usage summary:

    CPU time :                                   43876.61 sec.
    Max Memory :                                 82296 MB
    Average Memory :                             63563.98 MB
    Total Requested Memory :                     122880.00 MB
    Delta Memory :                               40584.00 MB
    Max Swap :                                   -
    Max Processes :                              51
    Max Threads :                                56
    Run time :                                   1666 sec.
    Turnaround time :                            1673 sec.

The output (if any) follows:

Importing data
= Run exp 1 of 4 =
com_2018_dm_100
08:03:56
Randomseed:  -1587713022
Randomseed:  -1364939999
Randomseed:  -1061421388
Randomseed:  1083994222
Randomseed:  -338101881
Randomseed:  -1159671325
Randomseed:  900009197
Randomseed:  149221280
Randomseed:  -1178352934
Randomseed:  -1297464737
Randomseed:  1219179824
Randomseed:  -275078972
Randomseed:  -1206395838
Randomseed:  -1802520833
Randomseed:  -41776951
Randomseed:  -2057604218
Randomseed:  -1112863197
Randomseed:  1595663549
Randomseed:  -374944242
Randomseed:  -1405548424
Randomseed:  -415371531
Randomseed:  379125397
Randomseed:  1701556624
Randomseed:  340000967
Randomseed:  -350318313
Randomseed:  972839627
Randomseed:  1328554912
Randomseed:  -898371798
Randomseed:  494203063
Randomseed:  1867266810
Randomseed:  2002096676
Randomseed:  -1719146663
Randomseed:  1883895425
Randomseed:  1846573783
Randomseed:  1680195255
Randomseed:  -861333008
Randomseed:  1936609080
Randomseed:  -485203102
Randomseed:  1692109359
Randomseed:  1973638764
Randomseed:  -247347986
Randomseed:  -35204194
Randomseed:  2072207644
Randomseed:  -606933433
Randomseed:  578140008
Randomseed:  2008210571
Randomseed:  558083796
Randomseed:  -106295498
multiprocessing.pool.RemoteTraceback: 
"""
Traceback (most recent call last):
  File "/cluster/apps/python/3.7.1/x86_64/lib64/python3.7/multiprocessing/pool.py", line 121, in worker
    result = (True, func(*args, **kwds))
  File "/cluster/apps/python/3.7.1/x86_64/lib64/python3.7/multiprocessing/pool.py", line 47, in starmapstar
    return list(itertools.starmap(args[0], args[1]))
  File "/cluster/home/anunezji/COSA_Tools/SimulateExperiment.py", line 190, in simulate_run
    sim_model.step()
  File "/cluster/home/anunezji/COSA_Model/SolarAdoptionModel.py", line 311, in step
    self.schedule.step()
  File "/cluster/home/anunezji/COSA_Tools/scheduler.py", line 53, in step
    getattr(self._agents[agent_key], stage)()  # Run stage
  File "/cluster/home/anunezji/COSA_Agent/BuildingAgent.py", line 332, in step_decision
    c_max_npv = self.pick_community_highest_npv(combinations_dict)
  File "/cluster/home/anunezji/COSA_Agent/BuildingAgent.py", line 792, in pick_community_highest_npv
    return k[v.index(max(v))]
TypeError: '>' not supported between instances of 'dict' and 'dict'
"""

The above exception was the direct cause of the following exception:

Traceback (most recent call last):
  File "COSA_main.py", line 61, in <module>
    exp_results = run_experiment(sc_inputs, BuildingAgent,         SolarAdoptionModel, agents_info, distances, solar, demand)
  File "/cluster/home/anunezji/COSA_Tools/SimulateExperiment.py", line 152, in run_experiment
    exp_results = p.starmap(simulate_run, run_inputs)
  File "/cluster/apps/python/3.7.1/x86_64/lib64/python3.7/multiprocessing/pool.py", line 298, in starmap
    return self._map_async(func, iterable, starmapstar, chunksize).get()
  File "/cluster/apps/python/3.7.1/x86_64/lib64/python3.7/multiprocessing/pool.py", line 683, in get
    raise self._value
TypeError: '>' not supported between instances of 'dict' and 'dict'
